Workbook

Sheet Supuestos
A1: INFRAEYE - SUPUESTOS DEL MODELO ECONÓMICO (USD)
A3: PARÁMETROS GENERALES
A4: Horizonte de evaluación (años) | B4: 5
A5: Tasa de descuento anual (WACC) | B5: 0.18
A6: Crecimiento anual de costos fijos - Optimista | B6: 0.1
A7: Crecimiento anual de costos fijos - Pesimista | B7: 0.08
A8: Costo variable por cliente (USD/año) | B8: 6
A10: PRECIOS DE SUSCRIPCIÓN (USD/mes)
A11: Plan Starter (hasta 10 recursos) | B11: 10
A12: Plan Professional (hasta 25 recursos) | B12: 50
A13: Plan Enterprise (recursos ilimitados - estimado) | B13: 200
A15: INVERSIÓN INICIAL - AÑO 0 (USD)
A16: Desarrollo del MVP (2 desarrolladores, 12 meses) | B16: 18000
A17: Infraestructura y herramientas iniciales | B17: 2000
A18: Marketing de lanzamiento | B18: 3000
A19: Gastos legales y de registración | B19: 1500
A20: Capital de trabajo inicial | B20: 2500
A21: TOTAL INVERSIÓN INICIAL | B21: =SUM(B16:B20)
A23: COSTOS FIJOS ANUALES - AÑO 1, ESCENARIO OPTIMISTA (USD)
A24: Infraestructura cloud (backend, BD, monitoreo) | B24: 3600
A25: Herramientas y licencias | B25: 1200
A26: Marketing y ventas | B26: 4800
A27: Personal (2 desarrolladores + soporte) | B27: 24000
A28: Gastos administrativos y contables | B28: 1800
A29: TOTAL COSTOS FIJOS AÑO 1 - OPTIMISTA | B29: =SUM(B24:B28)
A31: COSTOS FIJOS ANUALES - AÑO 1, ESCENARIO PESIMISTA (USD)
A32: Infraestructura cloud (backend, BD, monitoreo) | B32: 3600
A33: Herramientas y licencias | B33: 1200
A34: Marketing y ventas (reducido) | B34: 2400
A35: Personal (soporte part-time, socios sin retiro) | B35: 9600
A36: Gastos administrativos y contables | B36: 1200
A37: TOTAL COSTOS FIJOS AÑO 1 - PESIMISTA | B37: =SUM(B32:B36)
A39: CLIENTES ACTIVOS PROMEDIO POR AÑO - ESCENARIO OPTIMISTA
B40: Año 1 | C40: Año 2 | D40: Año 3 | E40: Año 4 | F40: Año 5
A41: Plan Starter | B41: 120 | C41: 300 | D41: 600 | E41: 1000 | F41: 1500
A42: Plan Professional | B42: 30 | C42: 80 | D42: 180 | E42: 320 | F42: 500
A43: Plan Enterprise | B43: 3 | C43: 10 | D43: 25 | E43: 45 | F43: 70
A45: CLIENTES ACTIVOS PROMEDIO POR AÑO - ESCENARIO PESIMISTA
B46: Año 1 | C46: Año 2 | D46: Año 3 | E46: Año 4 | F46: Año 5
A47: Plan Starter | B47: 40 | C47: 70 | D47: 110 | E47: 150 | F47: 190
...

Sheet Optimista
A1: ESCENARIO OPTIMISTA - FLUJO DE FONDOS (USD)
A3: Concepto | B3: Año 0 | C3: Año 1 | D3: Año 2 | E3: Año 3 | F3: Año 4 | G3: Año 5
A4: CLIENTES ACTIVOS PROMEDIO
A5: Plan Starter | C5: =Supuestos!B41 | D5: =Supuestos!C41 | E5: =Supuestos!D41 | F5: =Supuestos!E41 | G5: =Supuestos!F41
A6: Plan Professional | C6: =Supuestos!B42 | D6: =Supuestos!C42 | E6: =Supuestos!D42 | F6: =Supuestos!E42 | G6: =Supuestos!F42
A7: Plan Enterprise | C7: =Supuestos!B43 | D7: =Supuestos!C43 | E7: =Supuestos!D43 | F7: =Supuestos!E43 | G7: =Supuestos!F43
A8: Total clientes | C8: =SUM(C5:C7) | D8: =SUM(D5:D7) | E8: =SUM(E5:E7) | F8: =SUM(F5:F7) | G8: =SUM(G5:G7)
A10: INGRESOS POR SUSCRIPCIONES (USD)
A11: Ingresos Plan Starter ($10/mes) | C11: =C5*Supuestos!$B$11*12 | D11: =D5*Supuestos!$B$11*12 | E11: =E5*Supuestos!$B$11*12 | F11: =F5*Supuestos!$B$11*12 | G11: =G5*Supuestos!$B$11*12
A12: Ingresos Plan Professional ($50/mes) | C12: =C6*Supuestos!$B$12*12 | D12: =D6*Supuestos!$B$12*12 | E12: =E6*Supuestos!$B$12*12 | F12: =F6*Supuestos!$B$12*12 | G12: =G6*Supuestos!$B$12*12
A13: Ingresos Plan Enterprise ($200/mes) | C13: =C7*Supuestos!$B$13*12 | D13: =D7*Supuestos!$B$13*12 | E13: =E7*Supuestos!$B$13*12 | F13: =F7*Supuestos!$B$13*12 | G13: =G7*Supuestos!$B$13*12
A14: TOTAL INGRESOS | C14: =SUM(C11:C13) | D14: =SUM(D11:D13) | E14: =SUM(E11:E13) | F14: =SUM(F11:F13) | G14: =SUM(G11:G13)
A16: EGRESOS OPERATIVOS (USD)
A17: Costos fijos operativos | C17: =Supuestos!$B$29 | D17: =C17*(1+Supuestos!$B$6) | E17: =D17*(1+Supuestos!$B$6) | F17: =E17*(1+Supuestos!$B$6) | G17: =F17*(1+Supuestos!$B$6)
A18: Costos variables (por cliente) | C18: =C8*Supuestos!$B$8 | D18: =D8*Supuestos!$B$8 | E18: =E8*Supuestos!$B$8 | F18: =F8*Supuestos!$B$8 | G18: =G8*Supuestos!$B$8
A19: TOTAL EGRESOS | C19: =C17+C18 | D19: =D17+D18 | E19: =E17+E18 | F19: =F17+F18 | G19: =G17+G18
A21: FLUJO DE FONDOS (USD)
A22: Inversión inicial (Año 0) | B22: =-Supuestos!$B$21
A23: Flujo neto del año | B23: =B22 | C23: =C14-C19 | D23: =D14-D19 | E23: =E14-E19 | F23: =F14-F19 | G23: =G14-G19
A24: Flujo neto acumulado | B24: =B23 | C24: =B24+C23 | D24: =C24+D23 | E24: =D24+E23 | F24: =E24+F23 | G24: =F24+G23
A26: PUNTO DE EQUILIBRIO (por año)
A27: Margen de contribución sobre ingresos | C27: =1-C18/C14 | D27: =1-D18/D14 | E27: =1-E18/E14 | F27: =1-F18/F14 | G27: =1-G18/G14
A28: Ingresos necesarios para equilibrio (USD) | C28: =C17/C27 | D28: =D17/D27 | E28: =E17/E27 | F28: =F17/F27 | G28: =G17/G27
A29: ¿El año supera el punto de equilibrio? | C29: =IF(C14>=C28,"Sí","No") | D29: =IF(D14>=D28,"Sí","No") | E29: =IF(E14>=E28,"Sí","No") | F29: =IF(F14>=F28,"Sí","No") | G29: =IF(G14>=G28,"Sí","No")

Sheet Pesimista
A1: ESCENARIO PESIMISTA - FLUJO DE FONDOS (USD)
A3: Concepto | B3: Año 0 | C3: Año 1 | D3: Año 2 | E3: Año 3 | F3: Año 4 | G3: Año 5
A4: CLIENTES ACTIVOS PROMEDIO
A5: Plan Starter | C5: =Supuestos!B47 | D5: =Supuestos!C47 | E5: =Supuestos!D47 | F5: =Supuestos!E47 | G5: =Supuestos!F47
A6: Plan Professional | C6: =Supuestos!B48 | D6: =Supuestos!C48 | E6: =Supuestos!D48 | F6: =Supuestos!E48 | G6: =Supuestos!F48
A7: Plan Enterprise | C7: =Supuestos!B49 | D7: =Supuestos!C49 | E7: =Supuestos!D49 | F7: =Supuestos!E49 | G7: =Supuestos!F49
A8: Total clientes | C8: =SUM(C5:C7) | D8: =SUM(D5:D7) | E8: =SUM(E5:E7) | F8: =SUM(F5:F7) | G8: =SUM(G5:G7)
A10: INGRESOS POR SUSCRIPCIONES (USD)
A11: Ingresos Plan Starter ($10/mes) | C11: =C5*Supuestos!$B$11*12 | D11: =D5*Supuestos!$B$11*12 | E11: =E5*Supuestos!$B$11*12 | F11: =F5*Supuestos!$B$11*12 | G11: =G5*Supuestos!$B$11*12
A12: Ingresos Plan Professional ($50/mes) | C12: =C6*Supuestos!$B$12*12 | D12: =D6*Supuestos!$B$12*12 | E12: =E6*Supuestos!$B$12*12 | F12: =F6*Supuestos!$B$12*12 | G12: =G6*Supuestos!$B$12*12
A13: Ingresos Plan Enterprise ($200/mes) | C13: =C7*Supuestos!$B$13*12 | D13: =D7*Supuestos!$B$13*12 | E13: =E7*Supuestos!$B$13*12 | F13: =F7*Supuestos!$B$13*12 | G13: =G7*Supuestos!$B$13*12
A14: TOTAL INGRESOS | C14: =SUM(C11:C13) | D14: =SUM(D11:D13) | E14: =SUM(E11:E13) | F14: =SUM(F11:F13) | G14: =SUM(G11:G13)
A16: EGRESOS OPERATIVOS (USD)
A17: Costos fijos operativos | C17: =Supuestos!$B$37 | D17: =C17*(1+Supuestos!$B$7) | E17: =D17*(1+Supuestos!$B$7) | F17: =E17*(1+Supuestos!$B$7) | G17: =F17*(1+Supuestos!$B$7)
A18: Costos variables (por cliente) | C18: =C8*Supuestos!$B$8 | D18: =D8*Supuestos!$B$8 | E18: =E8*Supuestos!$B$8 | F18: =F8*Supuestos!$B$8 | G18: =G8*Supuestos!$B$8
A19: TOTAL EGRESOS | C19: =C17+C18 | D19: =D17+D18 | E19: =E17+E18 | F19: =F17+F18 | G19: =G17+G18
A21: FLUJO DE FONDOS (USD)
A22: Inversión inicial (Año 0) | B22: =-Supuestos!$B$21
A23: Flujo neto del año | B23: =B22 | C23: =C14-C19 | D23: =D14-D19 | E23: =E14-E19 | F23: =F14-F19 | G23: =G14-G19
A24: Flujo neto acumulado | B24: =B23 | C24: =B24+C23 | D24: =C24+D23 | E24: =D24+E23 | F24: =E24+F23 | G24: =F24+G23
A26: PUNTO DE EQUILIBRIO (por año)
A27: Margen de contribución sobre ingresos | C27: =1-C18/C14 | D27: =1-D18/D14 | E27: =1-E18/E14 | F27: =1-F18/F14 | G27: =1-G18/G14
A28: Ingresos necesarios para equilibrio (USD) | C28: =C17/C27 | D28: =D17/D27 | E28: =E17/E27 | F28: =F17/F27 | G28: =G17/G27
A29: ¿El año supera el punto de equilibrio? | C29: =IF(C14>=C28,"Sí","No") | D29: =IF(D14>=D28,"Sí","No") | E29: =IF(E14>=E28,"Sí","No") | F29: =IF(F14>=F28,"Sí","No") | G29: =IF(G14>=G28,"Sí","No")

Sheet Indicadores
A1: INFRAEYE - EVALUACIÓN ECONÓMICA (TIR, VAN, PAYBACK Y PUNTO DE EQUILIBRIO)
A3: Indicador | B3: OPTIMISTA | C3: PESIMISTA
A4: Inversión inicial (USD) | B4: =Supuestos!B21 | C4: =Supuestos!B21
A5: TIR (horizonte 5 años) | B5: =IRR(Optimista!B23:G23) | C5: =IRR(Pesimista!B23:G23)
A6: VAN al WACC (USD) | B6: =NPV(Supuestos!B5,Optimista!C23:G23)+Optimista!B23 | C6: =NPV(Supuestos!B5,Pesimista!C23:G23)+Pesimista!B23
A7: Payback (años) | B7: =IF(COUNTIF(Optimista!B24:G24,"<0")=0,0,IF(COUNTIF(Optimista!B24:G24,"<0")=6,"No se recupera en el horizonte",(COUNTIF(Optimista!B24:G24,"<0")-1)+ABS(INDEX(Optimista!B24:G24,COUNTIF(Optimista!B24:G24,"<0")))/INDEX(Optimista!B23:G23,COUNTIF(Optimista!B24:G24,"<0")+1))) | C7: =IF(COUNTIF(Pesimista!B24:G24,"<0")=0,0,IF(COUNTIF(Pesimista!B24:G24,"<0")=6,"No se recupera en el horizonte",(COUNTIF(Pesimista!B24:G24,"<0")-1)+ABS(INDEX(Pesimista!B24:G24,COUNTIF(Pesimista!B24:G24,"<0")))/INDEX(Pesimista!B23:G23,COUNTIF(Pesimista!B24:G24,"<0")+1)))
A8: Flujo neto acumulado al Año 5 (USD) | B8: =Optimista!G24 | C8: =Pesimista!G24
A9: Ingresos Año 1 (USD) | B9: =Optimista!C14 | C9: =Pesimista!C14
A10: Punto de equilibrio Año 1 (USD de ingresos) | B10: =Optimista!C28 | C10: =Pesimista!C28
A11: Primer año con flujo neto positivo | B11: =IF(Optimista!C23>=0,1,IF(Optimista!D23>=0,2,IF(Optimista!E23>=0,3,IF(Optimista!F23>=0,4,IF(Optimista!G23>=0,5,"Ninguno"))))) | C11: =IF(Pesimista!C23>=0,1,IF(Pesimista!D23>=0,2,IF(Pesimista!E23>=0,3,IF(Pesimista!F23>=0,4,IF(Pesimista!G23>=0,5,"Ninguno")))))
A13: CONCLUSIONES (se actualizan automáticamente)
A14: Escenario Optimista | B14: =IF(AND(B5>Supuestos!B5,B6>0),"Proyecto viable: la TIR supera la tasa de descuento y el VAN es positivo.","Proyecto no viable: la rentabilidad no alcanza la tasa de descuento requerida.")
A15: Escenario Pesimista | B15: =IF(AND(C5>Supuestos!B5,C6>0),"Proyecto viable: la TIR supera la tasa de descuento y el VAN es positivo.","Proyecto no viable: la rentabilidad no alcanza la tasa de descuento requerida.")
